Workbook

Sheet Cover
A10: (Project 224008)
A12: VOLUME IV
A14: BOQ
B47: Rev. T00 - Issued for Tender- 23rd September 2024

Sheet BILL 1 TO 14
A1: Item | B1: Description of Works | C1: Unit | D1: QTY | E1: RATE ( AED ) | F1: TOTAL Item PRICE ( AED )
B3: BILL NO. 1 : PRELIMINARIES
B4: These General Requirements are applicable to the whole of the works each item, clause or sub-clause must be individually priced. The Tenderer shall not enter any lump-sums covering more than one or all items, clauses or sub-clauses. Note: Where any item, clause, or sub clause of the preliminaries has not been priced, it will be deemed that the value of such item, clause or sub clause is included in the rates for measured items elsewhere in the bills of quantities. Any Work not specified in drawings, specification, BOQ but required as per local authorities and necessary to complete work to be included in the Main Contractors scope of work.
A5: 1.01 | B5: Provide site compound, workshops, secure storage areas, temporary external lighting, plant, roads, car shed ,etc. and remove on completion, including that for all Nominated Sub-Contractors | C5: Item | F5: =IFERROR(E5*D5,0) -> 0
A6: 1.02 | B6: Allow for any extreme physical constraints of the site | C6: Item | F6: =IFERROR(E6*D6,0) -> 0
A7: 1.03 | B7: Allow for protecting all the Works from the weather, damage, theft, including that of all Nominated Sub- Contractors and clearing away same on completion | C7: Item | F7: =IFERROR(E7*D7,0) -> 0
A8: 1.04 | B8: Allow for protecting all finished Work, including that of all Nominated Sub-Contractors, from damage however caused and theft | C8: Item | F8: =IFERROR(E8*D8,0) -> 0
A9: 1.05 | B9: Allow for temporary covering to excavations and other hazards | C9: Item | F9: =IFERROR(E9*D9,0) -> 0
A10: 1.06 | B10: Allow for temporary barricading to excavations, structural openings, shafts, exposed floor ends, roofs and all other hazards, etc. | C10: Item | F10: =IFERROR(E10*D10,0) -> 0
A11: 1.07 | B11: Allow for keeping the Site, roads, footpaths and any adjacent areas affected by the Works clear of debris and other rubbish during the progress of the Work and on completion | C11: Item | F11: =IFERROR(E11*D11,0) -> 0
A12: 1.08 | B12: Allow for site administration, Contractor Staff Sallaries, Overhead, Profits, supervision, security, safety, pest control, health and overtime (including any overtime requirements for the Engineer Representatives) | C12: Item | F12: =IFERROR(E12*D12,0) -> 0
A13: 1.09 | B13: Allow for hoarding and fencing requirements including regular maintenance and decoration with all gates and access and egress points, including removal on completion | C13: Item | F13: =IFERROR(E13*D13,0) -> 0
A14: 1.1 | B14: Allow for protecting adjacent roads and footpaths, working areas, etc. from falling debris, etc. from overhead works, including safety protection fans for all elevations, at all levels, including relocation to suit the course of the works | C14: Item | F14: =IFERROR(E14*D14,0) -> 0
A15: 1.11 | B15: Allow for providing plant and tools | C15: Item | F15: =IFERROR(E15*D15,0) -> 0
A16: 1.12 | B16: Allow for providing all scaffolding and cradles and maintaining with regular servicing and checks (including for all Nominated Sub-Contractors requirements) | C16: Item | F16: =IFERROR(E16*D16,0) -> 0
... A38: 1.34 | B38: Allow for including and considering (at the time of tendering and signing Contract agreement ) federal corporate tax on business profits applicable and imposed by UAE Government effective since June 2023. | C38: Item | F38: =IFERROR(E38*D38,0) -> 0
B39: Additional Items: The contractor to detail below any additional Items (with quantities and rates) shown in the drawings, mentioned in the specs. And /or required for satisfactory completion of the buildup of the lump sum project price of this section of works. Should the contractor fail to insert any Item in this section, it will be deemed that his lump sum price for the entire project included all Items and no subsequent claim for any additional Items will be entertained. | F39: =IFERROR(E39*D39,0) -> 0
F40: =IFERROR(E40*D40,0) -> 0
F41: =IFERROR(E41*D41,0) -> 0
F42: =IFERROR(E42*D42,0) -> 0
F43: =IFERROR(E43*D43,0) -> 0
F44: =IFERROR(E44*D44,0) -> 0
F56: =IFERROR(E56*D56,0) -> 0
F57: =IFERROR(E57*D57,0) -> 0
F58: =IFERROR(E58*D58,0) -> 0
F59: =IFERROR(E59*D59,0) -> 0
F60: =IFERROR(E60*D60,0) -> 0
F61: =IFERROR(E61*D61,0) -> 0
F62: =IFERROR(E62*D62,0) -> 0
... F68: =IFERROR(E68*D68,0) -> 0
B69: Total Bill No. 1 Carried To Collection | F69: =SUM(F5:F68) -> 0
B70: BILL NO. 2 : SUB-STRUCTURE
A71: 2.01 | B71: Excavation for Foundation, UG Water tank, holding tanks, UG facilities, etc., starting from the excavation level of the Existing natural ground level up to bottom of foundation | F71: =IFERROR(E71*D71,0) -> 0
A72: a | B72: Excavation | C72: m3 | F72: =IFERROR(E72*D72,0) -> 0
A73: b | B73: Shoring Works (If Required) | C73: m | F73: =IFERROR(E73*D73,0) -> 0
A74: c | B74: Dewatering Works | C74: LS | F74: =IFERROR(E74*D74,0) -> 0
A75: 2.02 | B75: Remove surplus excavated materials from the site | C75: L.S. | F75: =IFERROR(E75*D75,0) -> 0
B76: Piling Works | F76: =IFERROR(E76*D76,0) -> 0
A77: a | B77: Pilling Work | C77: LS | F77: =IFERROR(E77*D77,0) -> 0
A78: b | B78: All pilling tests as per spec. | C78: LS | F78: =IFERROR(E78*D78,0) -> 0
...

Sheet SUMMARY
A1: COLLECTION OF BILLS No. 1 to 14 : SUMMARY PAGE
A2: 1 | B2: PRELIMINARIES | F2: ='BILL 1 TO 14'!F69 -> 0
A3: 2 | B3: SUB-STRUCTURE | F3: ='BILL 1 TO 14'!F109 -> 0
A4: 3 | B4: SUPER-STRUCTURE | F4: ='BILL 1 TO 14'!F148 -> 0
A5: 4 | B5: BLOCKWORK | F5: ='BILL 1 TO 14'!F170 -> 0
A6: 5 | B6: WATERPROOFING WORKS | F6: ='BILL 1 TO 14'!F193 -> 0
A7: 6 | B7: CARPENTRY& JOINERY WORKS | F7: ='BILL 1 TO 14'!F232 -> 0
A8: 7 | B8: METAL & GLAZING WORKS | F8: ='BILL 1 TO 14'!F306 -> 0
A9: 8 | B9: FINISHING WORKS | F9: ='BILL 1 TO 14'!F361 -> 0
A10: 9 | B10: MECHANICAL WORKS | F10: ='BILL 1 TO 14'!F511 -> 0
A11: 10 | B11: ELECTRICAL SYSTEM | F11: ='BILL 1 TO 14'!F662 -> 0
A12: 11 | B12: NATURAL GAS SYSTEM | F12: ='BILL 1 TO 14'!F688 -> 0
A13: 12 | B13: EXTERNAL WORKS | F13: ='BILL 1 TO 14'!F705 -> 0
A14: 13 | B14: FITTING, FIXTURES & EQUIPMENT | F14: ='BILL 1 TO 14'!F721 -> 0
A15: 14 | B15: PROVISIONAL SUMS | F15: ='BILL 1 TO 14'!F751 -> 1440000
A16: SUB-TOTAL (Before Discount) | F16: =SUM(F2:F15) -> 1440000
A17: Tenderer's Price Adjustment, Discount (%)
A18: GRAND TOTAL PROJECT PRICE (AED) | F18: =SUM(F16:F17) -> 1440000
B20: TOTAL AMOUNT IN WORDS
B21: Dhs…...............................................................................................................................................
B22: …...…...........................................................................................................................................
B24: SIGNATURE OF TENDERER STAMP OF TENDERER
